<?xml version="1.0" ?>
<!-- =================================================================================== -->
<!-- |    This document was autogenerated by xacro from /home/colin/chessrobot_simulation/catkin_ws/src/myur5_description/urdf/myur5_gripper.urdf.xacro | -->
<!-- |    EDITING THIS FILE BY HAND IS NOT RECOMMENDED                                 | -->
<!-- =================================================================================== -->
<robot name="ur5e_robot">
    <!--
    Main xacro macro definition of the "Gazebo robot" model.

    This wraps the model of the real robot and adds all elements and parameters
    required by Gazebo.

    It also adds the gazebo_ros_control plugin.

    NOTE: this is NOT a URDF. It cannot directly be loaded by consumers
    expecting a flattened '.urdf' file. See the top-level '.xacro' for that
    (but note: that .xacro must still be processed by the xacro command).

    For use in '.launch' files: use one of the 'load_urX.launch' convenience
    launch files.

    NOTE: this Gazebo model makes use of the same set of parameter files as the
    main xacro macro (in ur_description). It is therefor possible to use the
    kinematic calibration exported from a REAL UR robot. Please refer to the
    ur_macro.xacro in ur_description for more information about this.

    Main author of the migration to yaml configs: Ludovic Delval.

    Contributors to previous versions (in no particular order):

     - Felix Messmer
     - Kelsey Hawkins
     - Shaun Edwards
     - Alexander Bubeck
     - Nadia Hammoudeh Garcia
     - G. vd. Hoorn
     - Dave Niewinski
     - Andy Zelenak
     - Miguel Prada
     - Mathias Luedtke
     - Hans-Joachim Krauch
     - Felix Exner
  -->
    <!--
    Base UR robot series xacro macro.

    NOTE: this is NOT a URDF. It cannot directly be loaded by consumers
    expecting a flattened '.urdf' file. See the top-level '.xacro' for that
    (but note: that .xacro must still be processed by the xacro command).

    For use in '.launch' files: use one of the 'load_urX.launch' convenience
    launch files.

    This file models the base kinematic chain of a UR robot, which then gets
    parameterised by various configuration files to convert it into a UR3(e),
    UR5(e), UR10(e), UR16e or UR20.

    NOTE: the default kinematic parameters (ie: link lengths, frame locations,
    offets, etc) do not correspond to any particular robot. They are defaults
    only. There WILL be non-zero offsets between the Forward Kinematics results
    in TF (ie: robot_state_publisher) and the values reported by the Teach
    Pendant.

    For accurate (and robot-specific) transforms, the 'kinematics_parameters_file'
    parameter MUST point to a .yaml file containing the appropriate values for
    the targetted robot.

    If using the UniversalRobots/Universal_Robots_ROS_Driver, follow the steps
    described in the readme of that repository to extract the kinematic
    calibration from the controller and generate the required .yaml file.

    Main author of the migration to yaml configs: Ludovic Delval.

    Contributors to previous versions (in no particular order):

     - Felix Messmer
     - Kelsey Hawkins
     - Wim Meeussen
     - Shaun Edwards
     - Nadia Hammoudeh Garcia
     - Dave Hershberger
     - G. vd. Hoorn
     - Philip Long
     - Dave Coleman
     - Miguel Prada
     - Mathias Luedtke
     - Marcel Schnirring
     - Felix von Drigalski
     - Felix Exner
     - Jimmy Da Silva
     - Ajit Krisshna N L
     - Muhammad Asif Rana
  -->
    <!--
    NOTE: the macro defined in this file is NOT part of the public API of this
          package. Users CANNOT rely on this file being available, or stored in
          this location. Nor can they rely on the existence of the macro.
  -->
    <transmission name="shoulder_pan_trans">
        <type>transmission_interface/SimpleTransmission</type>
        <joint name="shoulder_pan_joint">
            <hardwareInterface>hardware_interface/EffortJointInterface</hardwareInterface>
        </joint>
        <actuator name="shoulder_pan_motor">
            <mechanicalReduction>1</mechanicalReduction>
            <hardwareInterface>hardware_interface/EffortJointInterface</hardwareInterface>
        </actuator>
    </transmission>
    <transmission name="shoulder_lift_trans">
        <type>transmission_interface/SimpleTransmission</type>
        <joint name="shoulder_lift_joint">
            <hardwareInterface>hardware_interface/EffortJointInterface</hardwareInterface>
        </joint>
        <actuator name="shoulder_lift_motor">
            <mechanicalReduction>1</mechanicalReduction>
            <hardwareInterface>hardware_interface/EffortJointInterface</hardwareInterface>
        </actuator>
    </transmission>
    <transmission name="elbow_trans">
        <type>transmission_interface/SimpleTransmission</type>
        <joint name="elbow_joint">
            <hardwareInterface>hardware_interface/EffortJointInterface</hardwareInterface>
        </joint>
        <actuator name="elbow_motor">
            <mechanicalReduction>1</mechanicalReduction>
            <hardwareInterface>hardware_interface/EffortJointInterface</hardwareInterface>
        </actuator>
    </transmission>
    <transmission name="wrist_1_trans">
        <type>transmission_interface/SimpleTransmission</type>
        <joint name="wrist_1_joint">
            <hardwareInterface>hardware_interface/EffortJointInterface</hardwareInterface>
        </joint>
        <actuator name="wrist_1_motor">
            <mechanicalReduction>1</mechanicalReduction>
            <hardwareInterface>hardware_interface/EffortJointInterface</hardwareInterface>
        </actuator>
    </transmission>
    <transmission name="wrist_2_trans">
        <type>transmission_interface/SimpleTransmission</type>
        <joint name="wrist_2_joint">
            <hardwareInterface>hardware_interface/EffortJointInterface</hardwareInterface>
        </joint>
        <actuator name="wrist_2_motor">
            <mechanicalReduction>1</mechanicalReduction>
            <hardwareInterface>hardware_interface/EffortJointInterface</hardwareInterface>
        </actuator>
    </transmission>
    <transmission name="wrist_3_trans">
        <type>transmission_interface/SimpleTransmission</type>
        <joint name="wrist_3_joint">
            <hardwareInterface>hardware_interface/EffortJointInterface</hardwareInterface>
        </joint>
        <actuator name="wrist_3_motor">
            <mechanicalReduction>1</mechanicalReduction>
            <hardwareInterface>hardware_interface/EffortJointInterface</hardwareInterface>
        </actuator>
    </transmission>
    <!-- links: main serial chain -->
    <link name="base_link" />
    <link name="base_link_inertia">
        <visual>
            <origin rpy="0 0 3.141592653589793" xyz="0 0 0" />
            <geometry>
                <mesh filename="package://ur_description/meshes/ur5e/visual/base.dae" />
            </geometry>
            <material name="LightGrey">
                <color rgba="0.7 0.7 0.7 1.0" />
            </material>
        </visual>
        <collision>
            <origin rpy="0 0 3.141592653589793" xyz="0 0 0" />
            <geometry>
                <mesh filename="package://ur_description/meshes/ur5e/collision/base.stl" />
            </geometry>
        </collision>
        <inertial>
            <mass value="4.0" />
            <origin rpy="0 0 0" xyz="0 0 0" />
            <inertia ixx="0.00443333156" ixy="0.0" ixz="0.0" iyy="0.00443333156" iyz="0.0" izz="0.0072" />
        </inertial>
    </link>
    <link name="shoulder_link">
        <visual>
            <origin rpy="0 0 3.141592653589793" xyz="0 0 0" />
            <geometry>
                <mesh filename="package://ur_description/meshes/ur5e/visual/shoulder.dae" />
            </geometry>
            <material name="LightGrey">
                <color rgba="0.7 0.7 0.7 1.0" />
            </material>
        </visual>
        <collision>
            <origin rpy="0 0 3.141592653589793" xyz="0 0 0" />
            <geometry>
                <mesh filename="package://ur_description/meshes/ur5e/collision/shoulder.stl" />
            </geometry>
        </collision>
        <inertial>
            <mass value="3.7" />
            <origin rpy="0 0 0" xyz="0 0 0" />
            <inertia ixx="0.010267495893" ixy="0.0" ixz="0.0" iyy="0.010267495893" iyz="0.0" izz="0.00666" />
        </inertial>
    </link>
    <link name="upper_arm_link">
        <visual>
            <origin rpy="1.5707963267948966 0 -1.5707963267948966" xyz="0 0 0.138" />
            <geometry>
                <mesh filename="package://ur_description/meshes/ur5e/visual/upperarm.dae" />
            </geometry>
            <material name="LightGrey">
                <color rgba="0.7 0.7 0.7 1.0" />
            </material>
        </visual>
        <collision>
            <origin rpy="1.5707963267948966 0 -1.5707963267948966" xyz="0 0 0.138" />
            <geometry>
                <mesh filename="package://ur_description/meshes/ur5e/collision/upperarm.stl" />
            </geometry>
        </collision>
        <inertial>
            <mass value="8.393" />
            <origin rpy="0 1.5707963267948966 0" xyz="-0.2125 0.0 0.138" />
            <inertia ixx="0.1338857818623325" ixy="0.0" ixz="0.0" iyy="0.1338857818623325" iyz="0.0" izz="0.0151074" />
        </inertial>
    </link>
    <link name="forearm_link">
        <visual>
            <origin rpy="1.5707963267948966 0 -1.5707963267948966" xyz="0 0 0.007" />
            <geometry>
                <mesh filename="package://ur_description/meshes/ur5e/visual/forearm.dae" />
            </geometry>
            <material name="LightGrey">
                <color rgba="0.7 0.7 0.7 1.0" />
            </material>
        </visual>
        <collision>
            <origin rpy="1.5707963267948966 0 -1.5707963267948966" xyz="0 0 0.007" />
            <geometry>
                <mesh filename="package://ur_description/meshes/ur5e/collision/forearm.stl" />
            </geometry>
        </collision>
        <inertial>
            <mass value="2.275" />
            <origin rpy="0 1.5707963267948966 0" xyz="-0.1961 0.0 0.007" />
            <inertia ixx="0.031209355099586295" ixy="0.0" ixz="0.0" iyy="0.031209355099586295" iyz="0.0" izz="0.004095" />
        </inertial>
    </link>
    <link name="wrist_1_link">
        <visual>
            <!-- TODO: Move this to a parameter -->
            <origin rpy="1.5707963267948966 0 0" xyz="0 0 -0.127" />
            <geometry>
                <mesh filename="package://ur_description/meshes/ur5e/visual/wrist1.dae" />
            </geometry>
            <material name="LightGrey">
                <color rgba="0.7 0.7 0.7 1.0" />
            </material>
        </visual>
        <collision>
            <origin rpy="1.5707963267948966 0 0" xyz="0 0 -0.127" />
            <geometry>
                <mesh filename="package://ur_description/meshes/ur5e/collision/wrist1.stl" />
            </geometry>
        </collision>
        <inertial>
            <mass value="1.219" />
            <origin rpy="0 0 0" xyz="0 0 0" />
            <inertia ixx="0.0025598989760400002" ixy="0.0" ixz="0.0" iyy="0.0025598989760400002" iyz="0.0" izz="0.0021942" />
        </inertial>
    </link>
    <link name="wrist_2_link">
        <visual>
            <origin rpy="0 0 0" xyz="0 0 -0.0997" />
            <geometry>
                <mesh filename="package://ur_description/meshes/ur5e/visual/wrist2.dae" />
            </geometry>
            <material name="LightGrey">
                <color rgba="0.7 0.7 0.7 1.0" />
            </material>
        </visual>
        <collision>
            <origin rpy="0 0 0" xyz="0 0 -0.0997" />
            <geometry>
                <mesh filename="package://ur_description/meshes/ur5e/collision/wrist2.stl" />
            </geometry>
        </collision>
        <inertial>
            <mass value="1.219" />
            <origin rpy="0 0 0" xyz="0 0 0" />
            <inertia ixx="0.0025598989760400002" ixy="0.0" ixz="0.0" iyy="0.0025598989760400002" iyz="0.0" izz="0.0021942" />
        </inertial>
    </link>
    <link name="wrist_3_link">
        <visual>
            <origin rpy="1.5707963267948966 0 0" xyz="0 0 -0.0989" />
            <geometry>
                <mesh filename="package://ur_description/meshes/ur5e/visual/wrist3.dae" />
            </geometry>
            <material name="LightGrey">
                <color rgba="0.7 0.7 0.7 1.0" />
            </material>
        </visual>
        <collision>
            <origin rpy="1.5707963267948966 0 0" xyz="0 0 -0.0989" />
            <geometry>
                <mesh filename="package://ur_description/meshes/ur5e/collision/wrist3.stl" />
            </geometry>
        </collision>
        <inertial>
            <mass value="0.1879" />
            <origin rpy="0 0 0" xyz="0.0 0.0 -0.0229" />
            <inertia ixx="9.890410052167731e-05" ixy="0.0" ixz="0.0" iyy="9.890410052167731e-05" iyz="0.0" izz="0.0001321171875" />
        </inertial>
    </link>
    <!-- joints: main serial chain -->
    <joint name="base_link-base_link_inertia" type="fixed">
        <parent link="base_link" />
        <child link="base_link_inertia" />
        <!-- 'base_link' is REP-103 aligned (so X+ forward), while the internal
           frames of the robot/controller have X+ pointing backwards.
           Use the joint between 'base_link' and 'base_link_inertia' (a dummy
           link/frame) to introduce the necessary rotation over Z (of pi rad).
      -->
        <origin rpy="0 0 3.141592653589793" xyz="0 0 0" />
    </joint>
    <joint name="shoulder_pan_joint" type="revolute">
        <parent link="base_link_inertia" />
        <child link="shoulder_link" />
        <origin rpy="0 0 0" xyz="0 0 0.1625" />
        <axis xyz="0 0 1" />
        <limit effort="150.0" lower="-6.283185307179586" upper="6.283185307179586" velocity="3.141592653589793" />
        <dynamics damping="0" friction="0" />
    </joint>
    <joint name="shoulder_lift_joint" type="revolute">
        <parent link="shoulder_link" />
        <child link="upper_arm_link" />
        <origin rpy="1.570796327 0 0" xyz="0 0 0" />
        <axis xyz="0 0 1" />
        <limit effort="150.0" lower="-6.283185307179586" upper="6.283185307179586" velocity="3.141592653589793" />
        <dynamics damping="0" friction="0" />
    </joint>
    <joint name="elbow_joint" type="revolute">
        <parent link="upper_arm_link" />
        <child link="forearm_link" />
        <origin rpy="0 0 0" xyz="-0.425 0 0" />
        <axis xyz="0 0 1" />
        <limit effort="150.0" lower="-3.141592653589793" upper="3.141592653589793" velocity="3.141592653589793" />
        <dynamics damping="0" friction="0" />
    </joint>
    <joint name="wrist_1_joint" type="revolute">
        <parent link="forearm_link" />
        <child link="wrist_1_link" />
        <origin rpy="0 0 0" xyz="-0.3922 0 0.1333" />
        <axis xyz="0 0 1" />
        <limit effort="28.0" lower="-6.283185307179586" upper="6.283185307179586" velocity="3.141592653589793" />
        <dynamics damping="0" friction="0" />
    </joint>
    <joint name="wrist_2_joint" type="revolute">
        <parent link="wrist_1_link" />
        <child link="wrist_2_link" />
        <origin rpy="1.570796327 0 0" xyz="0 -0.0997 -2.044881182297852e-11" />
        <axis xyz="0 0 1" />
        <limit effort="28.0" lower="-6.283185307179586" upper="6.283185307179586" velocity="3.141592653589793" />
        <dynamics damping="0" friction="0" />
    </joint>
    <joint name="wrist_3_joint" type="revolute">
        <parent link="wrist_2_link" />
        <child link="wrist_3_link" />
        <origin rpy="1.570796326589793 3.141592653589793 3.141592653589793" xyz="0 0.0996 -2.042830148012698e-11" />
        <axis xyz="0 0 1" />
        <limit effort="28.0" lower="-6.283185307179586" upper="6.283185307179586" velocity="3.141592653589793" />
        <dynamics damping="0" friction="0" />
    </joint>
    <!-- ROS-Industrial 'base' frame: base_link to UR 'Base' Coordinates transform -->
    <link name="base" />
    <joint name="base_link-base_fixed_joint" type="fixed">
        <!-- Note the rotation over Z of pi radians: as base_link is REP-103
           aligned (ie: has X+ forward, Y+ left and Z+ up), this is needed
           to correctly align 'base' with the 'Base' coordinate system of
           the UR controller.
      -->
        <origin rpy="0 0 3.141592653589793" xyz="0 0 0" />
        <parent link="base_link" />
        <child link="base" />
    </joint>
    <!-- ROS-Industrial 'flange' frame: attachment point for EEF models -->
    <link name="flange" />
    <joint name="wrist_3-flange" type="fixed">
        <parent link="wrist_3_link" />
        <child link="flange" />
        <origin rpy="0 -1.5707963267948966 -1.5707963267948966" xyz="0 0 0" />
    </joint>
    <!-- ROS-Industrial 'tool0' frame: all-zeros tool frame -->
    <link name="tool0" />
    <joint name="flange-tool0" type="fixed">
        <!-- default toolframe: X+ left, Y+ up, Z+ front -->
        <origin rpy="1.5707963267948966 0 1.5707963267948966" xyz="0 0 0" />
        <parent link="flange" />
        <child link="tool0" />
    </joint>
    <!-- Configure self collision properties per link -->
    <gazebo reference="shoulder_link">
        <selfCollide>true</selfCollide>
        <plugin name="gazebo_ros_control">
            <robotNamespace>/</robotNamespace>
        </plugin>
    </gazebo>
    <gazebo reference="upper_arm_link">
        <selfCollide>true</selfCollide>
    </gazebo>
    <gazebo reference="forearm_link">
        <selfCollide>true</selfCollide>
    </gazebo>
    <gazebo reference="wrist_1_link">
        <selfCollide>true</selfCollide>
    </gazebo>
    <gazebo reference="wrist_3_link">
        <selfCollide>true</selfCollide>
    </gazebo>
    <gazebo reference="wrist_2_link">
        <selfCollide>true</selfCollide>
    </gazebo>
    <gazebo reference="ee_link">
        <selfCollide>true</selfCollide>
    </gazebo>
    <!--
      Inject Gazebo ROS Control plugin, which allows us to use ros_control
      controllers to control the virtual robot hw.
    -->
    <gazebo>
        <plugin filename="libgazebo_ros_control.so" name="ros_control">
            <!--robotNamespace>/</robotNamespace-->
            <!--robotSimType>gazebo_ros_control/DefaultRobotHWSim</robotSimType-->
        </plugin>
    </gazebo>
    <!--
    Attach the Gazebo model to Gazebo's world frame.

    Note: if you're looking to integrate a UR into a larger scene and need
    to add EEFs or other parts, DO NOT change this file or the 'world' link
    here. Create a NEW xacro instead and decide whether you need to add
    a 'world' link there.
  -->
    <link name="world" />
    <!-- Define UR robot integration -->
    <link name="pedestal">
        <inertial>
            <origin rpy="0 0 0" xyz="0 0 0.025" />
            <mass value="20" />
            <inertia ixx="200" ixy="200" ixz="200" iyy="200" iyz="200" izz="200" />
        </inertial>
        <visual>
            <origin rpy="0 0 0" xyz="0 0 0.025" />
            <geometry>
                <cylinder length="0.05" radius="0.1" />
            </geometry>
            <material name="gray">
                <color rgba="0.5 0.5 0.5 0" />
            </material>
        </visual>
        <collision>
            <origin rpy="0 0 0" xyz="0 0 0.025" />
            <geometry>
                <cylinder length="0.05" radius="0.1" />
            </geometry>
        </collision>
    </link>
    <Gazebo reference="pedestal">
        <mu1>0.2</mu1>
        <mu2>0.2</mu2>
        <material>Gazebo/Orange</material>
    </Gazebo>
    <joint name="pedestal_to_world" type="fixed">
        <origin rpy="0 0 0" xyz="0 0 0" />
        <parent link="world" />
        <child link="pedestal" />
    </joint>
    <joint name="pedastal_joint" type="fixed">
        <origin rpy="0 0 0" xyz="0 0 0.05" />
        <parent link="pedestal" />
        <child link="base_link" />
    </joint>
    <!-- Robotiq Coupler -->
    <!--  + Height added by the coupler: 8mm -->
    <!--  + Reference frame: at the middle (4mm) -->
    <link name="robotiq_coupler">
        <visual>
            <geometry>
                <mesh filename="package://robotiq_description/meshes/robotiq_85_coupler.stl" />
            </geometry>
            <material name="flat_black" />
        </visual>
        <collision>
            <geometry>
                <mesh filename="package://robotiq_description/meshes/robotiq_85_coupler.stl" />
            </geometry>
        </collision>
        <inertial>
            <origin rpy="0 0 0" xyz="2.073e-05   1.45286e-03  -1.1049e-03" />
            <mass value="0.168" />
            <inertia ixx="6.69695624e-05" ixy="5.21511788e-09" ixz="-2.74383009e-08" iyy="7.85088161e-05" iyz="5.41105193e-07" izz="1.41819717e-04" />
        </inertial>
    </link>
    <joint name="robotiq_coupler_joint" type="fixed">
        <origin rpy="0 0 -1.5707963267948966" xyz="0 0 0.004" />
        <parent link="tool0" />
        <child link="robotiq_coupler" />
    </joint>
    <gazebo reference="robotiq_coupler">
        <mu1>0.9</mu1>
        <mu2>0.9</mu2>
        <material>Gazebo/FlatBlack</material>
    </gazebo>
    <!-- Equivalent to the OpenRAVE manipulator denso_robotiq_85_gripper -->
    <!-- <link name="denso_robotiq_85_gripper" /> -->
    <!-- <joint name="manipulator_dummy_joint" type="fixed"> -->
    <!--   <origin xyz="0 0 0.1441" rpy="0 0 0" /> -->
    <!--   <parent link="robotiq_coupler"/> -->
    <!--   <child link="denso_robotiq_85_gripper"/> -->
    <!-- </joint> -->
    <joint name="robotiq_85_base_joint" type="fixed">
        <parent link="robotiq_coupler" />
        <child link="robotiq_85_base_link" />
        <origin rpy="0 -1.5707963267948966 3.141592653589793" xyz="0 0 0.004" />
    </joint>
    <link name="robotiq_85_base_link">
        <visual>
            <geometry>
                <mesh filename="package://robotiq_description/meshes/visual/robotiq_85_base_link.dae" />
            </geometry>
        </visual>
        <collision>
            <geometry>
                <mesh filename="package://robotiq_description/meshes/collision/robotiq_85_base_link.stl" />
            </geometry>
        </collision>
        <inertial>
            <mass value="0.636951" />
            <origin xyz="0.0 0.0 0.0" rpy="0 0 0" />
            <inertia ixx="0.000380" ixy="0.000000" ixz="0.000000" iyx="0.000000" iyy="0.001110" iyz="0.000000" izx="0.000000" izy="0.000000" izz="0.001171" />
        </inertial>
    </link>
    <joint name="robotiq_85_left_knuckle_joint" type="revolute">
        <parent link="robotiq_85_base_link" />
        <child link="robotiq_85_left_knuckle_link" />
        <axis xyz="0 0 1" />
        <origin rpy="3.141592653589793 0.0 0.0" xyz="0.05490451627 0.03060114443 0.0" />
        <limit effort="1000" lower="0.0" upper="0.80285" velocity="0.5" />
    </joint>
    <joint name="robotiq_85_right_knuckle_joint" type="continuous">
        <parent link="robotiq_85_base_link" />
        <child link="robotiq_85_right_knuckle_link" />
        <axis xyz="0 0 1" />
        <origin rpy="0.0 0.0 0.0" xyz="0.05490451627 -0.03060114443 0.0" />
        <limit effort="1000" lower="-3.14" upper="3.14" velocity="100.0" />
        <mimic joint="robotiq_85_left_knuckle_joint" />
    </joint>
    <link name="robotiq_85_left_knuckle_link">
        <visual>
            <geometry>
                <mesh filename="package://robotiq_description/meshes/visual/robotiq_85_knuckle_link.dae" />
            </geometry>
        </visual>
        <collision>
            <geometry>
                <mesh filename="package://robotiq_description/meshes/collision/robotiq_85_knuckle_link.stl" />
            </geometry>
        </collision>
        <inertial>
            <mass value="0.018491" />
            <origin xyz="0.0 0.0 0.0" rpy="0 0 0" />
            <inertia ixx="0.000009" ixy="-0.000001" ixz="0.000000" iyx="-0.000001" iyy="0.000001" iyz="0.000000" izx="0.000000" izy="0.000000" izz="0.000010" />
        </inertial>
    </link>
    <link name="robotiq_85_right_knuckle_link">
        <visual>
            <geometry>
                <mesh filename="package://robotiq_description/meshes/visual/robotiq_85_knuckle_link.dae" />
            </geometry>
        </visual>
        <collision>
            <geometry>
                <mesh filename="package://robotiq_description/meshes/collision/robotiq_85_knuckle_link.stl" />
            </geometry>
        </collision>
        <inertial>
            <mass value="0.018491" />
            <origin xyz="0.0 0.0 0.0" rpy="0 0 0" />
            <inertia ixx="0.000009" ixy="-0.000001" ixz="0.000000" iyx="-0.000001" iyy="0.000001" iyz="0.000000" izx="0.000000" izy="0.000000" izz="0.000010" />
        </inertial>
    </link>
    <joint name="robotiq_85_left_finger_joint" type="fixed">
        <parent link="robotiq_85_left_knuckle_link" />
        <child link="robotiq_85_left_finger_link" />
        <origin rpy="0 0 0" xyz="-0.00408552455 -0.03148604435 0.0" />
    </joint>
    <joint name="robotiq_85_right_finger_joint" type="fixed">
        <parent link="robotiq_85_right_knuckle_link" />
        <child link="robotiq_85_right_finger_link" />
        <origin rpy="0 0 0" xyz="-0.00408552455 -0.03148604435 0.0" />
    </joint>
    <link name="robotiq_85_left_finger_link">
        <visual>
            <geometry>
                <mesh filename="package://robotiq_description/meshes/visual/robotiq_85_finger_link.dae" />
            </geometry>
        </visual>
        <collision>
            <geometry>
                <mesh filename="package://robotiq_description/meshes/collision/robotiq_85_finger_link.stl" />
            </geometry>
        </collision>
        <inertial>
            <mass value="0.027309" />
            <origin xyz="0.0 0.0 0.0" rpy="0 0 0" />
            <inertia ixx="0.000003" ixy="-0.000002" ixz="0.000000" iyx="-0.000002" iyy="0.000021" iyz="0.000000" izx="0.000000" izy="0.000000" izz="0.000020" />
        </inertial>
    </link>
    <link name="robotiq_85_right_finger_link">
        <visual>
            <geometry>
                <mesh filename="package://robotiq_description/meshes/visual/robotiq_85_finger_link.dae" />
            </geometry>
        </visual>
        <collision>
            <geometry>
                <mesh filename="package://robotiq_description/meshes/collision/robotiq_85_finger_link.stl" />
            </geometry>
        </collision>
        <inertial>
            <mass value="0.027309" />
            <origin xyz="0.0 0.0 0.0" rpy="0 0 0" />
            <inertia ixx="0.000003" ixy="-0.000002" ixz="0.000000" iyx="-0.000002" iyy="0.000021" iyz="0.000000" izx="0.000000" izy="0.000000" izz="0.000020" />
        </inertial>
    </link>
    <joint name="robotiq_85_left_inner_knuckle_joint" type="continuous">
        <parent link="robotiq_85_base_link" />
        <child link="robotiq_85_left_inner_knuckle_link" />
        <axis xyz="0 0 1" />
        <origin rpy="3.141592653589793 0.0 0.0" xyz="0.06142 0.0127 0" />
        <limit effort="0.1" lower="-3.14" upper="3.14" velocity="100.0" />
        <mimic joint="robotiq_85_left_knuckle_joint" offset="0" />
    </joint>
    <joint name="robotiq_85_right_inner_knuckle_joint" type="continuous">
        <parent link="robotiq_85_base_link" />
        <child link="robotiq_85_right_inner_knuckle_link" />
        <axis xyz="0 0 1" />
        <origin rpy="0 0 0" xyz="0.06142 -0.0127 0" />
        <limit effort="0.1" lower="-3.14" upper="3.14" velocity="100.0" />
        <mimic joint="robotiq_85_left_knuckle_joint" offset="0" />
    </joint>
    <link name="robotiq_85_left_inner_knuckle_link">
        <visual>
            <geometry>
                <mesh filename="package://robotiq_description/meshes/visual/robotiq_85_inner_knuckle_link.dae" />
            </geometry>
        </visual>
        <collision>
            <geometry>
                <mesh filename="package://robotiq_description/meshes/collision/robotiq_85_inner_knuckle_link.stl" />
            </geometry>
        </collision>
        <inertial>
            <mass value="0.029951" />
            <origin xyz="0.0 0.0 0.0" rpy="0 0 0" />
            <inertia ixx="0.000039" ixy="0.000000" ixz="0.000000" iyx="0.000000" iyy="0.000005" iyz="0.000000" izx="0.000000" izy="0.000000" izz="0.000035" />
        </inertial>
    </link>
    <link name="robotiq_85_right_inner_knuckle_link">
        <visual>
            <geometry>
                <mesh filename="package://robotiq_description/meshes/visual/robotiq_85_inner_knuckle_link.dae" />
            </geometry>
        </visual>
        <collision>
            <geometry>
                <mesh filename="package://robotiq_description/meshes/collision/robotiq_85_inner_knuckle_link.stl" />
            </geometry>
        </collision>
        <inertial>
            <mass value="0.029951" />
            <origin xyz="0.0 0.0 0.0" rpy="0 0 0" />
            <inertia ixx="0.000039" ixy="0.000000" ixz="0.000000" iyx="0.000000" iyy="0.000005" iyz="0.000000" izx="0.000000" izy="0.000000" izz="0.000035" />
        </inertial>
    </link>
    <joint name="robotiq_85_left_finger_tip_joint" type="continuous">
        <parent link="robotiq_85_left_inner_knuckle_link" />
        <child link="robotiq_85_left_finger_tip_link" />
        <axis xyz="0 0 1" />
        <origin rpy="0.0 0.0 0.0" xyz="0.04303959807 -0.03759940821 0.0" />
        <limit effort="0.1" lower="-3.14" upper="3.14" velocity="100.0" />
        <mimic joint="robotiq_85_left_knuckle_joint" multiplier="-1" />
    </joint>
    <joint name="robotiq_85_right_finger_tip_joint" type="continuous">
        <parent link="robotiq_85_right_inner_knuckle_link" />
        <child link="robotiq_85_right_finger_tip_link" />
        <axis xyz="0 0 1" />
        <origin rpy="0.0 0.0 0.0" xyz="0.04303959807 -0.03759940821  0.0" />
        <limit effort="0.1" lower="-3.14" upper="3.14" velocity="100.0" />
        <mimic joint="robotiq_85_left_knuckle_joint" multiplier="-1" />
    </joint>
    <link name="robotiq_85_left_finger_tip_link">
        <visual>
            <geometry>
                <mesh filename="package://robotiq_description/meshes/visual/robotiq_85_finger_tip_link.dae" />
            </geometry>
        </visual>
        <collision>
            <geometry>
                <mesh filename="package://robotiq_description/meshes/collision/robotiq_85_finger_tip_link.stl" />
            </geometry>
        </collision>
        <inertial>
            <mass value="0.019555" />
            <origin xyz="0.0 0.0 0.0" rpy="0 0 0" />
            <inertia ixx="0.000002" ixy="0.000000" ixz="0.000000" iyx="0.000000" iyy="0.000005" iyz="0.000000" izx="0.000000" izy="0.000000" izz="0.000006" />
        </inertial>
    </link>
    <link name="robotiq_85_right_finger_tip_link">
        <visual>
            <geometry>
                <mesh filename="package://robotiq_description/meshes/visual/robotiq_85_finger_tip_link.dae" />
            </geometry>
        </visual>
        <collision>
            <geometry>
                <mesh filename="package://robotiq_description/meshes/collision/robotiq_85_finger_tip_link.stl" />
            </geometry>
        </collision>
        <inertial>
            <mass value="0.019555" />
            <origin xyz="0.0 0.0 0.0" rpy="0 0 0" />
            <inertia ixx="0.000002" ixy="0.000000" ixz="0.000000" iyx="0.000000" iyy="0.000005" iyz="0.000000" izx="0.000000" izy="0.000000" izz="0.000006" />
        </inertial>
    </link>
    <!-- Improve grasping physics -->
    <gazebo reference="robotiq_85_left_finger_tip_link">
        <kp>1000000.0</kp>
        <kd>1.0</kd>
        <mu1>1.0</mu1>
        <mu2>1.0</mu2>
        <minDepth>0.001</minDepth>
    </gazebo>
    <gazebo reference="robotiq_85_right_finger_tip_link">
        <kp>1000000.0</kp>
        <kd>1.0</kd>
        <mu1>1.0</mu1>
        <mu2>1.0</mu2>
        <minDepth>0.001</minDepth>
    </gazebo>
    <transmission name="robotiq_85_left_knuckle_trans">
        <type>transmission_interface/SimpleTransmission</type>
        <joint name="robotiq_85_left_knuckle_joint">
            <hardwareInterface>hardware_interface/EffortJointInterface</hardwareInterface>
            <!-- <hardwareInterface>EffortJointInterface</hardwareInterface> -->
        </joint>
        <actuator name="robotiq_85_left_knuckle_motor">
            <mechanicalReduction>1</mechanicalReduction>
            <hardwareInterface>hardware_interface/EffortJointInterface</hardwareInterface>
            <!-- <hardwareInterface>EfforJointInterface</hardwareInterface> -->
        </actuator>
    </transmission>
    <!-- Mimic joints -->
    <gazebo>
        <plugin filename="libgazebo_mimic_joint_plugin.so" name="mimic_robotiq_85_1">
            <joint>robotiq_85_left_knuckle_joint</joint>
            <mimicJoint>robotiq_85_right_knuckle_joint</mimicJoint>
        </plugin>
        <plugin filename="libgazebo_mimic_joint_plugin.so" name="mimic_robotiq_85_2">
            <joint>robotiq_85_left_knuckle_joint</joint>
            <mimicJoint>robotiq_85_left_inner_knuckle_joint</mimicJoint>
        </plugin>
        <plugin filename="libgazebo_mimic_joint_plugin.so" name="mimic_robotiq_85_3">
            <joint>robotiq_85_left_knuckle_joint</joint>
            <mimicJoint>robotiq_85_right_inner_knuckle_joint</mimicJoint>
        </plugin>
        <plugin filename="libgazebo_mimic_joint_plugin.so" name="mimic_robotiq_85_4">
            <joint>robotiq_85_left_knuckle_joint</joint>
            <mimicJoint>robotiq_85_left_finger_tip_joint</mimicJoint>
            <multiplier>-1.0</multiplier>
            <offset>0.0</offset>
        </plugin>
        <plugin filename="libgazebo_mimic_joint_plugin.so" name="mimic_robotiq_85_5">
            <joint>robotiq_85_left_knuckle_joint</joint>
            <mimicJoint>robotiq_85_right_finger_tip_joint</mimicJoint>
            <multiplier>-1.0</multiplier>
            <offset>0.0</offset>
        </plugin>
    </gazebo>
    <!-- Gazebo FT sensor plugin -->
    <gazebo reference="wrist_3_joint">
        <provideFeedback>true</provideFeedback>
    </gazebo>
    <gazebo>
        <plugin filename="libgazebo_ros_ft_sensor.so" name="ft_sensor_plugin">
            <updateRate>250.0</updateRate>
            <topicName>ft_sensor/raw</topicName>
            <gaussianNoise>0.0</gaussianNoise>
            <jointName>wrist_3_joint</jointName>
        </plugin>
    </gazebo>
    <!-- Gazebo grasping plugin -->
    <gazebo>
        <gripper name="gazebo_gripper">
            <grasp_check>
                <attach_steps>2</attach_steps>
                <!-- default: 20 -->
                <detach_steps>2</detach_steps>
                <!-- default: 40 -->
                <min_contact_count>3</min_contact_count>
            </grasp_check>
            <gripper_link>robotiq_85_left_finger_tip_link</gripper_link>
            <gripper_link>robotiq_85_right_finger_tip_link</gripper_link>
            <palm_link>robotiq_85_base_link</palm_link>
        </gripper>
    </gazebo>
    <transmission name="trans_robotiq_85_right_knuckle_joint">
        <type>transmission_interface/SimpleTransmission</type>
        <joint name="robotiq_85_right_knuckle_joint">
            <hardwareInterface>hardware_interface/EffortJointInterface</hardwareInterface>
        </joint>
        <actuator name="robotiq_85_right_knuckle_joint_motor">
            <hardwareInterface>hardware_interface/EffortJointInterface</hardwareInterface>
            <mechanicalReduction>1</mechanicalReduction>
        </actuator>
    </transmission>
    <transmission name="trans_robotiq_85_left_inner_knuckle_joint">
        <type>transmission_interface/SimpleTransmission</type>
        <joint name="robotiq_85_left_inner_knuckle_joint">
            <hardwareInterface>hardware_interface/EffortJointInterface</hardwareInterface>
        </joint>
        <actuator name="robotiq_85_left_inner_knuckle_joint_motor">
            <hardwareInterface>hardware_interface/EffortJointInterface</hardwareInterface>
            <mechanicalReduction>1</mechanicalReduction>
        </actuator>
    </transmission>
    <transmission name="trans_robotiq_85_right_inner_knuckle_joint">
        <type>transmission_interface/SimpleTransmission</type>
        <joint name="robotiq_85_right_inner_knuckle_joint">
            <hardwareInterface>hardware_interface/EffortJointInterface</hardwareInterface>
        </joint>
        <actuator name="robotiq_85_right_inner_knuckle_joint_motor">
            <hardwareInterface>hardware_interface/EffortJointInterface</hardwareInterface>
            <mechanicalReduction>1</mechanicalReduction>
        </actuator>
    </transmission>
    <transmission name="trans_robotiq_85_left_finger_tip_joint">
        <type>transmission_interface/SimpleTransmission</type>
        <joint name="robotiq_85_left_finger_tip_joint">
            <hardwareInterface>hardware_interface/EffortJointInterface</hardwareInterface>
        </joint>
        <actuator name="robotiq_85_left_finger_tip_joint_motor">
            <hardwareInterface>hardware_interface/EffortJointInterface</hardwareInterface>
            <mechanicalReduction>1</mechanicalReduction>
        </actuator>
    </transmission>
    <transmission name="trans_robotiq_85_right_finger_tip_joint">
        <type>transmission_interface/SimpleTransmission</type>
        <joint name="robotiq_85_right_finger_tip_joint">
            <hardwareInterface>hardware_interface/EffortJointInterface</hardwareInterface>
        </joint>
        <actuator name="robotiq_85_right_finger_tip_joint_motor">
            <hardwareInterface>hardware_interface/EffortJointInterface</hardwareInterface>
            <mechanicalReduction>1</mechanicalReduction>
        </actuator>
    </transmission>
</robot>

